<?xml version="1.0" ?>
<robot name="cube_gripper_left.urdf">
  <link name="world"/>
  <link name="left_dummy_x">
    <inertial>
      <origin rpy="0 0 0" xyz="0 0 0"/>
       <mass value=".1"/>
       <inertia ixx="1" ixy="0" ixz="0" iyy="1" iyz="0" izz="1"/>
    </inertial>
  </link>
  <link name="left_dummy_y">
    <inertial>
      <origin rpy="0 0 0" xyz="0 0 0"/>
       <mass value=".1"/>
       <inertia ixx="1" ixy="0" ixz="0" iyy="1" iyz="0" izz="1"/>
    </inertial>
  </link>


  <link name="left_baseLink">
    <contact>
      <lateral_friction value="1.0"/>
      <spinning_friction value="0.3"/>
      <inertia_scaling value="3.0"/>
    </contact>
    <inertial>
      <origin rpy="0 0 0" xyz="0 0 0"/>
       <mass value="5.1"/>
       <inertia ixx="1" ixy="0" ixz="0" iyy="1" iyz="0" izz="1"/>
    </inertial>
    <visual>
      <origin xyz="0.0 0.0 0.0"/>
      <geometry>
				<mesh filename="cube.obj" scale=".05 .05 .05"/>
      </geometry>
       <material name="red">
        <color rgba="1 0 0 1"/>
      </material>
    </visual>
    <collision>
      <origin rpy="0 0.0 0.0" xyz="0. 0 2.4"/>
      <geometry>
	 	<box size=".05 .05 .05"/>
      </geometry>
    </collision>
  </link>

  <joint name="left_cube_joint_x" type="prismatic">
    <parent link="world"/>
    <child link="left_dummy_x"/>
    <origin rpy="0 0 0" xyz="0 0 0"/>
    <axis xyz="1 0 0"/>
    <limit effort="300" lower="-2.96705972839" upper="2.96705972839" velocity="1"/>
    <dynamics damping="0.0"/>
  </joint>
  <joint name="left_cube_joint_y" type="prismatic">
    <parent link="left_dummy_x"/>
    <child link="left_dummy_y"/>
    <origin rpy="0 0 0" xyz="0 0 0"/>
    <axis xyz="0 1 0"/>
    <limit effort="300" lower="-2.96705972839" upper="2.96705972839" velocity="1"/>
    <dynamics damping="0.0"/>
  </joint>
  <joint name="left_cube_joint_z" type="prismatic">
    <parent link="left_dummy_y"/>
    <child link="left_baseLink"/>
    <origin rpy="0 0 0" xyz="0 0 0"/>
    <axis xyz="0 0 1"/>
    <limit effort="300" lower="-2.96705972839" upper="2.96705972839" velocity="1"/>
    <dynamics damping="0.0"/>
  </joint>
</robot>
